Workbook

Sheet Assumptions
A1: art-store / shmetsy — Model Assumptions
A2: Edit yellow cells only. Everything else is a formula.
A3: PROFIT IS BEFORE FOUNDER COMPENSATION. Support salaries are modelled; your own pay is not.
A5: Blue = input you can change
A6: Black = formula
A7: Green = pulled from another sheet
A9: CORE DRIVERS | B9: Value | C9: Confidence | D9: Note
A10: GMV per seller / month — LOW | B10: 110 | C10: YOUR DIRECTION | D10: Approximates Etsy platform GMS / active sellers incl. dormant shops. Conservative floor, LOW confidence.
A11: GMV per seller / month — MID | B11: 500 | C11: YOUR DIRECTION | D11: Illustrative: modest but real side-business seller.
A12: GMV per seller / month — HIGH | B12: 2000 | C12: YOUR DIRECTION | D12: Illustrative: seller running this as primary income.
A13: Average order value (AOV) | B13: 50 | C13: UNVERIFIED | D13: Drives orders/mo and the cost of the fixed $0.30 processing fee.
A14: Payment processing — % of GMV | B14: 0.029 | C14: UNVERIFIED | D14: Stripe US card standard. NOT sourced in the research files.
A15: Payment processing — $ per order | B15: 0.3 | C15: UNVERIFIED | D15: Stripe US card standard. NOT sourced in the research files.
A16: Chargeback / refund loss — LOW | B16: 0.005 | C16: UNVERIFIED | D16: No sourced figure exists for art/handmade goods.
A17: Chargeback / refund loss — BASE | B17: 0.01 | C17: UNVERIFIED | D17: Base case used on the Model and Profit Targets tabs.
A18: Chargeback / refund loss — HIGH | B18: 0.02 | C18: UNVERIFIED | D18: Stress case.
A19: Support salary per FTE / year | B19: 80000 | C19: YOUR DIRECTION | D19: Base pay only. W-2 payroll burden (~20%) is NOT included.
A20: Sellers triggering 1st support FTE | B20: 200 | C20: YOUR DIRECTION | D20: Creates the hiring valley — see the Sensitivity tab.
A21: Sellers triggering 2nd support FTE | B21: 2000 | C21: YOUR DIRECTION
A22: Sellers triggering 3rd support FTE | B22: 10000 | C22: YOUR DIRECTION
A23: Retained earnings share of profit | B23: 0.5 | C23: YOUR DIRECTION | D23: Remainder distributed. Losses are absorbed whole, not split.
A24: Customer acquisition cost per seller | B24: 50 | C24: UNVERIFIED | D24: Illustrative placeholder. Only used to translate retained earnings into fundable growth.
A26: FEE TIERS (flat, all-in — platform absorbs processing and loss) | B26: Fee | C26: Net take @ base loss | D26: vs 6%
A27: Tier 1 | B27: 0.06 | C27: =B27-$B$14-($B$15/$B$13)-$B$17 -> 0.015 | D27: =IFERROR(C27/$C$27-1,0) -> 0
A28: Tier 2 | B28: 0.07 | C28: =B28-$B$14-($B$15/$B$13)-$B$17 -> 0.025 | D28: =IFERROR(C28/$C$27-1,0) -> 0.66666667
A29: Tier 3 | B29: 0.08 | C29: =B29-$B$14-($B$15/$B$13)-$B$17 -> 0.035 | D29: =IFERROR(C29/$C$27-1,0) -> 1.3333333
A30: Tier 4 | B30: 0.09 | C30: =B30-$B$14-($B$15/$B$13)-$B$17 -> 0.045 | D30: =IFERROR(C30/$C$27-1,0) -> 2
A32: SELLER SCENARIOS | B32: Sellers | C32: Support FTE | D32: Note
A33: Scenario 1 | B33: 10 | C33: =IF(B33>=$B$22,3,IF(B33>=$B$21,2,IF(B33>=$B$20,1,0))) -> 0 | D33: Support FTE derived from the hire thresholds above.
A34: Scenario 2 | B34: 100 | C34: =IF(B34>=$B$22,3,IF(B34>=$B$21,2,IF(B34>=$B$20,1,0))) -> 0 | D34: Support FTE derived from the hire thresholds above.
A35: Scenario 3 | B35: 1000 | C35: =IF(B35>=$B$22,3,IF(B35>=$B$21,2,IF(B35>=$B$20,1,0))) -> 1 | D35: Support FTE derived from the hire thresholds above.
A36: Scenario 4 | B36: 10000 | C36: =IF(B36>=$B$22,3,IF(B36>=$B$21,2,IF(B36>=$B$20,1,0))) -> 3 | D36: Support FTE derived from the hire thresholds above.
A38: NOT IN THIS MODEL
A39: - Founder compensation. The largest remaining omission — every profit figure is before paying yourself.
A40: - Customer acquisition as a P&L line. CAC appears only as a use of retained earnings, never as a cost of getting there.
A41: - Churn. Seller counts are stock, not flow. Holding 1,843 active sellers may mean acquiring 3,000+.
A42: - Buyer-side demand generation — the thing sellers actually pay a marketplace fee for. The core product risk.
A43: - Stripe Connect payout/transfer fees beyond base processing.
A44: - Marketplace facilitator sales tax and 1099-K issuance.
A45: - Payroll burden on salaries (~20% for W-2): about $48,000/yr at 3 FTE.

Sheet Costs
A1: Operating Cost Stack
A2: Software from tooling-costs-2-users.md and email-crm-costs.md. Labour per your hire thresholds.
A4: SOFTWARE, BY SELLER COUNT (monthly USD)
A5: Line | B5: 10 | C5: 100 | D5: 1,000 | E5: 10,000 | F5: Confidence
A6: Supabase | B6: 25 | C6: 25 | D6: 50 | E6: 225 | F6: HIGH at 10/100 - ESTIMATE at 1k/10k, no basis in the research.
A7: Cloudflare zone | B7: 0 | C7: 0 | D7: 20 | E7: 20 | F7: HIGH. Free covers CDN; Pro $20/mo annual at real traffic.
A8: Cloudflare Workers | B8: 5 | C8: 5 | D8: 25 | E8: 150 | F8: HIGH at 10/100 ($5 min) - ESTIMATE at 1k/10k.
A9: Canva Pro ($15/seat/mo) | B9: 30 | C9: 30 | D9: 60 | E9: 60 | F9: HIGH. Scales with staff seats (2/2/4/4).
A10: GitHub | B10: 0 | C10: 0 | D10: 16 | E10: 16 | F10: HIGH. Free to 2 staff; Team $4/user/mo thereafter.
A11: Domain | B11: 1.56 | C11: 1.56 | D11: 1.56 | E11: 1.56 | F11: HIGH. Fixed regardless of scale.
A12: Customer support | B12: 0 | C12: 0 | D12: 0 | E12: 0 | F12: HIGH. Help Scout Free at every scale - your decision that 1 inbox works.
A13: Email (Kit) | B13: 0 | C13: 0 | D13: 0 | E13: 100 | F13: HIGH to 10k subs - UNVERIFIED above. $100 is a placeholder.
A14: Claude Max 5x ($100/seat) | B14: 200 | C14: 200 | D14: 400 | E14: 400 | F14: HIGH. Team standard seats would cut this ~80% if limits suffice.
A15: Software / month | B15: =SUM(B6:B14) -> 261.56 | C15: =SUM(C6:C14) -> 261.56 | D15: =SUM(D6:D14) -> 572.56 | E15: =SUM(E6:E14) -> 972.56
A16: Software / year | B16: =B15*12 -> 3138.72 | C16: =C15*12 -> 3138.72 | D16: =D15*12 -> 6870.72 | E16: =E15*12 -> 11670.72
A17: Support FTE | B17: =Assumptions!$C$33 -> 0 | C17: =Assumptions!$C$34 -> 0 | D17: =Assumptions!$C$35 -> 1 | E17: =Assumptions!$C$36 -> 3
A18: Support labour / year | B18: =B17*Assumptions!$B$19 -> 0 | C18: =C17*Assumptions!$B$19 -> 0 | D18: =D17*Assumptions!$B$19 -> 80000 | E18: =E17*Assumptions!$B$19 -> 240000
A19: TOTAL OPERATING COST / YEAR | B19: =B16+B18 -> 3138.72 | C19: =C16+C18 -> 3138.72 | D19: =D16+D18 -> 86870.72 | E19: =E16+E18 -> 251670.72
A21: Labour dwarfs software past 200 sellers. At 10,000 sellers software is ~4.6% of operating cost.

Sheet Model
A1: Full Model — annual P&L at the base loss rate
A2: Every cell is a formula off Assumptions and Costs. Change the base loss rate to restress the whole grid.
A3: Support labour IS included. FOUNDER COMPENSATION AND CUSTOMER ACQUISITION ARE NOT.
A5: LOW GMV BAND
A6: GMV band | B6: GMV/seller/mo | C6: Sellers | D6: Annual GMV | E6: Fee | F6: Gross fee rev | G6: Processing | H6: Chargeback loss | I6: Net revenue | J6: Software | K6: Support labour | L6: Profit | M6: Retained | N6: Distributed | O6: Sellers fundable
A7: Low | B7: =Assumptions!$B$10 -> 110 | C7: =Assumptions!$B$33 -> 10 | D7: =B7*C7*12 -> 13200 | E7: =Assumptions!$B$27 -> 0.06 | F7: =D7*E7 -> 792 | G7: =-(D7*Assumptions!$B$14+IFERROR(D7/Assumptions!$B$13,0)*Assumptions!$B$15) -> -462 | H7: =-D7*Assumptions!$B$17 -> -132 | I7: =F7+G7+H7 -> 198 | J7: =-Costs!B$16 -> -3138.72 | K7: =-Costs!B$18 -> 0 | L7: =I7+J7+K7 -> -2940.72 | M7: =IF(L7>0,L7*Assumptions!$B$23,L7) -> -2940.72 | N7: =IF(L7>0,L7*(1-Assumptions!$B$23),0) -> 0 | O7: =IFERROR(MAX(M7,0)/Assumptions!$B$24,0) -> 0
A8: Low | B8: =Assumptions!$B$10 -> 110 | C8: =Assumptions!$B$33 -> 10 | D8: =B8*C8*12 -> 13200 | E8: =Assumptions!$B$28 -> 0.07 | F8: =D8*E8 -> 924 | G8: =-(D8*Assumptions!$B$14+IFERROR(D8/Assumptions!$B$13,0)*Assumptions!$B$15) -> -462 | H8: =-D8*Assumptions!$B$17 -> -132 | I8: =F8+G8+H8 -> 330 | J8: =-Costs!B$16 -> -3138.72 | K8: =-Costs!B$18 -> 0 | L8: =I8+J8+K8 -> -2808.72 | M8: =IF(L8>0,L8*Assumptions!$B$23,L8) -> -2808.72 | N8: =IF(L8>0,L8*(1-Assumptions!$B$23),0) -> 0 | O8: =IFERROR(MAX(M8,0)/Assumptions!$B$24,0) -> 0
A9: Low | B9: =Assumptions!$B$10 -> 110 | C9: =Assumptions!$B$33 -> 10 | D9: =B9*C9*12 -> 13200 | E9: =Assumptions!$B$29 -> 0.08 | F9: =D9*E9 -> 1056 | G9: =-(D9*Assumptions!$B$14+IFERROR(D9/Assumptions!$B$13,0)*Assumptions!$B$15) -> -462 | H9: =-D9*Assumptions!$B$17 -> -132 | I9: =F9+G9+H9 -> 462 | J9: =-Costs!B$16 -> -3138.72 | K9: =-Costs!B$18 -> 0 | L9: =I9+J9+K9 -> -2676.72 | M9: =IF(L9>0,L9*Assumptions!$B$23,L9) -> -2676.72 | N9: =IF(L9>0,L9*(1-Assumptions!$B$23),0) -> 0 | O9: =IFERROR(MAX(M9,0)/Assumptions!$B$24,0) -> 0
A10: Low | B10: =Assumptions!$B$10 -> 110 | C10: =Assumptions!$B$33 -> 10 | D10: =B10*C10*12 -> 13200 | E10: =Assumptions!$B$30 -> 0.09 | F10: =D10*E10 -> 1188 | G10: =-(D10*Assumptions!$B$14+IFERROR(D10/Assumptions!$B$13,0)*Assumptions!$B$15) -> -462 | H10: =-D10*Assumptions!$B$17 -> -132 | I10: =F10+G10+H10 -> 594 | J10: =-Costs!B$16 -> -3138.72 | K10: =-Costs!B$18 -> 0 | L10: =I10+J10+K10 -> -2544.72 | M10: =IF(L10>0,L10*Assumptions!$B$23,L10) -> -2544.72 | N10: =IF(L10>0,L10*(1-Assumptions!$B$23),0) -> 0 | O10: =IFERROR(MAX(M10,0)/Assumptions!$B$24,0) -> 0
A11: Low | B11: =Assumptions!$B$10 -> 110 | C11: =Assumptions!$B$34 -> 100 | D11: =B11*C11*12 -> 132000 | E11: =Assumptions!$B$27 -> 0.06 | F11: =D11*E11 -> 7920 | G11: =-(D11*Assumptions!$B$14+IFERROR(D11/Assumptions!$B$13,0)*Assumptions!$B$15) -> -4620 | H11: =-D11*Assumptions!$B$17 -> -1320 | I11: =F11+G11+H11 -> 1980 | J11: =-Costs!C$16 -> -3138.72 | K11: =-Costs!C$18 -> 0 | L11: =I11+J11+K11 -> -1158.72 | M11: =IF(L11>0,L11*Assumptions!$B$23,L11) -> -1158.72 | N11: =IF(L11>0,L11*(1-Assumptions!$B$23),0) -> 0 | O11: =IFERROR(MAX(M11,0)/Assumptions!$B$24,0) -> 0
A12: Low | B12: =Assumptions!$B$10 -> 110 | C12: =Assumptions!$B$34 -> 100 | D12: =B12*C12*12 -> 132000 | E12: =Assumptions!$B$28 -> 0.07 | F12: =D12*E12 -> 9240 | G12: =-(D12*Assumptions!$B$14+IFERROR(D12/Assumptions!$B$13,0)*Assumptions!$B$15) -> -4620 | H12: =-D12*Assumptions!$B$17 -> -1320 | I12: =F12+G12+H12 -> 3300 | J12: =-Costs!C$16 -> -3138.72 | K12: =-Costs!C$18 -> 0 | L12: =I12+J12+K12 -> 161.28 | M12: =IF(L12>0,L12*Assumptions!$B$23,L12) -> 80.64 | N12: =IF(L12>0,L12*(1-Assumptions!$B$23),0) -> 80.64 | O12: =IFERROR(MAX(M12,0)/Assumptions!$B$24,0) -> 1.6128
A13: Low | B13: =Assumptions!$B$10 -> 110 | C13: =Assumptions!$B$34 -> 100 | D13: =B13*C13*12 -> 132000 | E13: =Assumptions!$B$29 -> 0.08 | F13: =D13*E13 -> 10560 | G13: =-(D13*Assumptions!$B$14+IFERROR(D13/Assumptions!$B$13,0)*Assumptions!$B$15) -> -4620 | H13: =-D13*Assumptions!$B$17 -> -1320 | I13: =F13+G13+H13 -> 4620 | J13: =-Costs!C$16 -> -3138.72 | K13: =-Costs!C$18 -> 0 | L13: =I13+J13+K13 -> 1481.28 | M13: =IF(L13>0,L13*Assumptions!$B$23,L13) -> 740.64 | N13: =IF(L13>0,L13*(1-Assumptions!$B$23),0) -> 740.64 | O13: =IFERROR(MAX(M13,0)/Assumptions!$B$24,0) -> 14.8128
A14: Low | B14: =Assumptions!$B$10 -> 110 | C14: =Assumptions!$B$34 -> 100 | D14: =B14*C14*12 -> 132000 | E14: =Assumptions!$B$30 -> 0.09 | F14: =D14*E14 -> 11880 | G14: =-(D14*Assumptions!$B$14+IFERROR(D14/Assumptions!$B$13,0)*Assumptions!$B$15) -> -4620 | H14: =-D14*Assumptions!$B$17 -> -1320 | I14: =F14+G14+H14 -> 5940 | J14: =-Costs!C$16 -> -3138.72 | K14: =-Costs!C$18 -> 0 | L14: =I14+J14+K14 -> 2801.28 | M14: =IF(L14>0,L14*Assumptions!$B$23,L14) -> 1400.64 | N14: =IF(L14>0,L14*(1-Assumptions!$B$23),0) -> 1400.64 | O14: =IFERROR(MAX(M14,0)/Assumptions!$B$24,0) -> 28.0128
A15: Low | B15: =Assumptions!$B$10 -> 110 | C15: =Assumptions!$B$35 -> 1000 | D15: =B15*C15*12 -> 1320000 | E15: =Assumptions!$B$27 -> 0.06 | F15: =D15*E15 -> 79200 | G15: =-(D15*Assumptions!$B$14+IFERROR(D15/Assumptions!$B$13,0)*Assumptions!$B$15) -> -46200 | H15: =-D15*Assumptions!$B$17 -> -13200 | I15: =F15+G15+H15 -> 19800 | J15: =-Costs!D$16 -> -6870.72 | K15: =-Costs!D$18 -> -80000 | L15: =I15+J15+K15 -> -67070.72 | M15: =IF(L15>0,L15*Assumptions!$B$23,L15) -> -67070.72 | N15: =IF(L15>0,L15*(1-Assumptions!$B$23),0) -> 0 | O15: =IFERROR(MAX(M15,0)/Assumptions!$B$24,0) -> 0
A16: Low | B16: =Assumptions!$B$10 -> 110 | C16: =Assumptions!$B$35 -> 1000 | D16: =B16*C16*12 -> 1320000 | E16: =Assumptions!$B$28 -> 0.07 | F16: =D16*E16 -> 92400 | G16: =-(D16*Assumptions!$B$14+IFERROR(D16/Assumptions!$B$13,0)*Assumptions!$B$15) -> -46200 | H16: =-D16*Assumptions!$B$17 -> -13200 | I16: =F16+G16+H16 -> 33000 | J16: =-Costs!D$16 -> -6870.72 | K16: =-Costs!D$18 -> -80000 | L16: =I16+J16+K16 -> -53870.72 | M16: =IF(L16>0,L16*Assumptions!$B$23,L16) -> -53870.72 | N16: =IF(L16>0,L16*(1-Assumptions!$B$23),0) -> 0 | O16: =IFERROR(MAX(M16,0)/Assumptions!$B$24,0) -> 0
A17: Low | B17: =Assumptions!$B$10 -> 110 | C17: =Assumptions!$B$35 -> 1000 | D17: =B17*C17*12 -> 1320000 | E17: =Assumptions!$B$29 -> 0.08 | F17: =D17*E17 -> 105600 | G17: =-(D17*Assumptions!$B$14+IFERROR(D17/Assumptions!$B$13,0)*Assumptions!$B$15) -> -46200 | H17: =-D17*Assumptions!$B$17 -> -13200 | I17: =F17+G17+H17 -> 46200 | J17: =-Costs!D$16 -> -6870.72 | K17: =-Costs!D$18 -> -80000 | L17: =I17+J17+K17 -> -40670.72 | M17: =IF(L17>0,L17*Assumptions!$B$23,L17) -> -40670.72 | N17: =IF(L17>0,L17*(1-Assumptions!$B$23),0) -> 0 | O17: =IFERROR(MAX(M17,0)/Assumptions!$B$24,0) -> 0
A18: Low | B18: =Assumptions!$B$10 -> 110 | C18: =Assumptions!$B$35 -> 1000 | D18: =B18*C18*12 -> 1320000 | E18: =Assumptions!$B$30 -> 0.09 | F18: =D18*E18 -> 118800 | G18: =-(D18*Assumptions!$B$14+IFERROR(D18/Assumptions!$B$13,0)*Assumptions!$B$15) -> -46200 | H18: =-D18*Assumptions!$B$17 -> -13200 | I18: =F18+G18+H18 -> 59400 | J18: =-Costs!D$16 -> -6870.72 | K18: =-Costs!D$18 -> -80000 | L18: =I18+J18+K18 -> -27470.72 | M18: =IF(L18>0,L18*Assumptions!$B$23,L18) -> -27470.72 | N18: =IF(L18>0,L18*(1-Assumptions!$B$23),0) -> 0 | O18: =IFERROR(MAX(M18,0)/Assumptions!$B$24,0) -> 0
A19: Low | B19: =Assumptions!$B$10 -> 110 | C19: =Assumptions!$B$36 -> 10000 | D19: =B19*C19*12 -> 13200000 | E19: =Assumptions!$B$27 -> 0.06 | F19: =D19*E19 -> 792000 | G19: =-(D19*Assumptions!$B$14+IFERROR(D19/Assumptions!$B$13,0)*Assumptions!$B$15) -> -462000 | H19: =-D19*Assumptions!$B$17 -> -132000 | I19: =F19+G19+H19 -> 198000 | J19: =-Costs!E$16 -> -11670.72 | K19: =-Costs!E$18 -> -240000 | L19: =I19+J19+K19 -> -53670.72 | M19: =IF(L19>0,L19*Assumptions!$B$23,L19) -> -53670.72 | N19: =IF(L19>0,L19*(1-Assumptions!$B$23),0) -> 0 | O19: =IFERROR(MAX(M19,0)/Assumptions!$B$24,0) -> 0
A20: Low | B20: =Assumptions!$B$10 -> 110 | C20: =Assumptions!$B$36 -> 10000 | D20: =B20*C20*12 -> 13200000 | E20: =Assumptions!$B$28 -> 0.07 | F20: =D20*E20 -> 924000 | G20: =-(D20*Assumptions!$B$14+IFERROR(D20/Assumptions!$B$13,0)*Assumptions!$B$15) -> -462000 | H20: =-D20*Assumptions!$B$17 -> -132000 | I20: =F20+G20+H20 -> 330000 | J20: =-Costs!E$16 -> -11670.72 | K20: =-Costs!E$18 -> -240000 | L20: =I20+J20+K20 -> 78329.28 | M20: =IF(L20>0,L20*Assumptions!$B$23,L20) -> 39164.64 | N20: =IF(L20>0,L20*(1-Assumptions!$B$23),0) -> 39164.64 | O20: =IFERROR(MAX(M20,0)/Assumptions!$B$24,0) -> 783.2928
A21: Low | B21: =Assumptions!$B$10 -> 110 | C21: =Assumptions!$B$36 -> 10000 | D21: =B21*C21*12 -> 13200000 | E21: =Assumptions!$B$29 -> 0.08 | F21: =D21*E21 -> 1056000 | G21: =-(D21*Assumptions!$B$14+IFERROR(D21/Assumptions!$B$13,0)*Assumptions!$B$15) -> -462000 | H21: =-D21*Assumptions!$B$17 -> -132000 | I21: =F21+G21+H21 -> 462000 | J21: =-Costs!E$16 -> -11670.72 | K21: =-Costs!E$18 -> -240000 | L21: =I21+J21+K21 -> 210329.28 | M21: =IF(L21>0,L21*Assumptions!$B$23,L21) -> 105164.64 | N21: =IF(L21>0,L21*(1-Assumptions!$B$23),0) -> 105164.64 | O21: =IFERROR(MAX(M21,0)/Assumptions!$B$24,0) -> 2103.2928
A22: Low | B22: =Assumptions!$B$10 -> 110 | C22: =Assumptions!$B$36 -> 10000 | D22: =B22*C22*12 -> 13200000 | E22: =Assumptions!$B$30 -> 0.09 | F22: =D22*E22 -> 1188000 | G22: =-(D22*Assumptions!$B$14+IFERROR(D22/Assumptions!$B$13,0)*Assumptions!$B$15) -> -462000 | H22: =-D22*Assumptions!$B$17 -> -132000 | I22: =F22+G22+H22 -> 594000 | J22: =-Costs!E$16 -> -11670.72 | K22: =-Costs!E$18 -> -240000 | L22: =I22+J22+K22 -> 342329.28 | M22: =IF(L22>0,L22*Assumptions!$B$23,L22) -> 171164.64 | N22: =IF(L22>0,L22*(1-Assumptions!$B$23),0) -> 171164.64 | O22: =IFERROR(MAX(M22,0)/Assumptions!$B$24,0) -> 3423.2928
A25: MID GMV BAND
A26: GMV band | B26: GMV/seller/mo | C26: Sellers | D26: Annual GMV | E26: Fee | F26: Gross fee rev | G26: Processing | H26: Chargeback loss | I26: Net revenue | J26: Software | K26: Support labour | L26: Profit | M26: Retained | N26: Distributed | O26: Sellers fundable
A27: Mid | B27: =Assumptions!$B$11 -> 500 | C27: =Assumptions!$B$33 -> 10 | D27: =B27*C27*12 -> 60000 | E27: =Assumptions!$B$27 -> 0.06 | F27: =D27*E27 -> 3600 | G27: =-(D27*Assumptions!$B$14+IFERROR(D27/Assumptions!$B$13,0)*Assumptions!$B$15) -> -2100 | H27: =-D27*Assumptions!$B$17 -> -600 | I27: =F27+G27+H27 -> 900 | J27: =-Costs!B$16 -> -3138.72 | K27: =-Costs!B$18 -> 0 | L27: =I27+J27+K27 -> -2238.72 | M27: =IF(L27>0,L27*Assumptions!$B$23,L27) -> -2238.72 | N27: =IF(L27>0,L27*(1-Assumptions!$B$23),0) -> 0 | O27: =IFERROR(MAX(M27,0)/Assumptions!$B$24,0) -> 0
A28: Mid | B28: =Assumptions!$B$11 -> 500 | C28: =Assumptions!$B$33 -> 10 | D28: =B28*C28*12 -> 60000 | E28: =Assumptions!$B$28 -> 0.07 | F28: =D28*E28 -> 4200 | G28: =-(D28*Assumptions!$B$14+IFERROR(D28/Assumptions!$B$13,0)*Assumptions!$B$15) -> -2100 | H28: =-D28*Assumptions!$B$17 -> -600 | I28: =F28+G28+H28 -> 1500 | J28: =-Costs!B$16 -> -3138.72 | K28: =-Costs!B$18 -> 0 | L28: =I28+J28+K28 -> -1638.72 | M28: =IF(L28>0,L28*Assumptions!$B$23,L28) -> -1638.72 | N28: =IF(L28>0,L28*(1-Assumptions!$B$23),0) -> 0 | O28: =IFERROR(MAX(M28,0)/Assumptions!$B$24,0) -> 0
A29: Mid | B29: =Assumptions!$B$11 -> 500 | C29: =Assumptions!$B$33 -> 10 | D29: =B29*C29*12 -> 60000 | E29: =Assumptions!$B$29 -> 0.08 | F29: =D29*E29 -> 4800 | G29: =-(D29*Assumptions!$B$14+IFERROR(D29/Assumptions!$B$13,0)*Assumptions!$B$15) -> -2100 | H29: =-D29*Assumptions!$B$17 -> -600 | I29: =F29+G29+H29 -> 2100 | J29: =-Costs!B$16 -> -3138.72 | K29: =-Costs!B$18 -> 0 | L29: =I29+J29+K29 -> -1038.72 | M29: =IF(L29>0,L29*Assumptions!$B$23,L29) -> -1038.72 | N29: =IF(L29>0,L29*(1-Assumptions!$B$23),0) -> 0 | O29: =IFERROR(MAX(M29,0)/Assumptions!$B$24,0) -> 0
A30: Mid | B30: =Assumptions!$B$11 -> 500 | C30: =Assumptions!$B$33 -> 10 | D30: =B30*C30*12 -> 60000 | E30: =Assumptions!$B$30 -> 0.09 | F30: =D30*E30 -> 5400 | G30: =-(D30*Assumptions!$B$14+IFERROR(D30/Assumptions!$B$13,0)*Assumptions!$B$15) -> -2100 | H30: =-D30*Assumptions!$B$17 -> -600 | I30: =F30+G30+H30 -> 2700 | J30: =-Costs!B$16 -> -3138.72 | K30: =-Costs!B$18 -> 0 | L30: =I30+J30+K30 -> -438.72 | M30: =IF(L30>0,L30*Assumptions!$B$23,L30) -> -438.72 | N30: =IF(L30>0,L30*(1-Assumptions!$B$23),0) -> 0 | O30: =IFERROR(MAX(M30,0)/Assumptions!$B$24,0) -> 0
A31: Mid | B31: =Assumptions!$B$11 -> 500 | C31: =Assumptions!$B$34 -> 100 | D31: =B31*C31*12 -> 600000 | E31: =Assumptions!$B$27 -> 0.06 | F31: =D31*E31 -> 36000 | G31: =-(D31*Assumptions!$B$14+IFERROR(D31/Assumptions!$B$13,0)*Assumptions!$B$15) -> -21000 | H31: =-D31*Assumptions!$B$17 -> -6000 | I31: =F31+G31+H31 -> 9000 | J31: =-Costs!C$16 -> -3138.72 | K31: =-Costs!C$18 -> 0 | L31: =I31+J31+K31 -> 5861.28 | M31: =IF(L31>0,L31*Assumptions!$B$23,L31) -> 2930.64 | N31: =IF(L31>0,L31*(1-Assumptions!$B$23),0) -> 2930.64 | O31: =IFERROR(MAX(M31,0)/Assumptions!$B$24,0) -> 58.6128
A32: Mid | B32: =Assumptions!$B$11 -> 500 | C32: =Assumptions!$B$34 -> 100 | D32: =B32*C32*12 -> 600000 | E32: =Assumptions!$B$28 -> 0.07 | F32: =D32*E32 -> 42000 | G32: =-(D32*Assumptions!$B$14+IFERROR(D32/Assumptions!$B$13,0)*Assumptions!$B$15) -> -21000 | H32: =-D32*Assumptions!$B$17 -> -6000 | I32: =F32+G32+H32 -> 15000 | J32: =-Costs!C$16 -> -3138.72 | K32: =-Costs!C$18 -> 0 | L32: =I32+J32+K32 -> 11861.28 | M32: =IF(L32>0,L32*Assumptions!$B$23,L32) -> 5930.64 | N32: =IF(L32>0,L32*(1-Assumptions!$B$23),0) -> 5930.64 | O32: =IFERROR(MAX(M32,0)/Assumptions!$B$24,0) -> 118.6128
A33: Mid | B33: =Assumptions!$B$11 -> 500 | C33: =Assumptions!$B$34 -> 100 | D33: =B33*C33*12 -> 600000 | E33: =Assumptions!$B$29 -> 0.08 | F33: =D33*E33 -> 48000 | G33: =-(D33*Assumptions!$B$14+IFERROR(D33/Assumptions!$B$13,0)*Assumptions!$B$15) -> -21000 | H33: =-D33*Assumptions!$B$17 -> -6000 | I33: =F33+G33+H33 -> 21000 | J33: =-Costs!C$16 -> -3138.72 | K33: =-Costs!C$18 -> 0 | L33: =I33+J33+K33 -> 17861.28 | M33: =IF(L33>0,L33*Assumptions!$B$23,L33) -> 8930.64 | N33: =IF(L33>0,L33*(1-Assumptions!$B$23),0) -> 8930.64 | O33: =IFERROR(MAX(M33,0)/Assumptions!$B$24,0) -> 178.6128
A34: Mid | B34: =Assumptions!$B$11 -> 500 | C34: =Assumptions!$B$34 -> 100 | D34: =B34*C34*12 -> 600000 | E34: =Assumptions!$B$30 -> 0.09 | F34: =D34*E34 -> 54000 | G34: =-(D34*Assumptions!$B$14+IFERROR(D34/Assumptions!$B$13,0)*Assumptions!$B$15) -> -21000 | H34: =-D34*Assumptions!$B$17 -> -6000 | I34: =F34+G34+H34 -> 27000 | J34: =-Costs!C$16 -> -3138.72 | K34: =-Costs!C$18 -> 0 | L34: =I34+J34+K34 -> 23861.28 | M34: =IF(L34>0,L34*Assumptions!$B$23,L34) -> 11930.64 | N34: =IF(L34>0,L34*(1-Assumptions!$B$23),0) -> 11930.64 | O34: =IFERROR(MAX(M34,0)/Assumptions!$B$24,0) -> 238.6128
A35: Mid | B35: =Assumptions!$B$11 -> 500 | C35: =Assumptions!$B$35 -> 1000 | D35: =B35*C35*12 -> 6000000 | E35: =Assumptions!$B$27 -> 0.06 | F35: =D35*E35 -> 360000 | G35: =-(D35*Assumptions!$B$14+IFERROR(D35/Assumptions!$B$13,0)*Assumptions!$B$15) -> -210000 | H35: =-D35*Assumptions!$B$17 -> -60000 | I35: =F35+G35+H35 -> 90000 | J35: =-Costs!D$16 -> -6870.72 | K35: =-Costs!D$18 -> -80000 | L35: =I35+J35+K35 -> 3129.28 | M35: =IF(L35>0,L35*Assumptions!$B$23,L35) -> 1564.64 | N35: =IF(L35>0,L35*(1-Assumptions!$B$23),0) -> 1564.64 | O35: =IFERROR(MAX(M35,0)/Assumptions!$B$24,0) -> 31.2928
A36: Mid | B36: =Assumptions!$B$11 -> 500 | C36: =Assumptions!$B$35 -> 1000 | D36: =B36*C36*12 -> 6000000 | E36: =Assumptions!$B$28 -> 0.07 | F36: =D36*E36 -> 420000 | G36: =-(D36*Assumptions!$B$14+IFERROR(D36/Assumptions!$B$13,0)*Assumptions!$B$15) -> -210000 | H36: =-D36*Assumptions!$B$17 -> -60000 | I36: =F36+G36+H36 -> 150000 | J36: =-Costs!D$16 -> -6870.72 | K36: =-Costs!D$18 -> -80000 | L36: =I36+J36+K36 -> 63129.28 | M36: =IF(L36>0,L36*Assumptions!$B$23,L36) -> 31564.64 | N36: =IF(L36>0,L36*(1-Assumptions!$B$23),0) -> 31564.64 | O36: =IFERROR(MAX(M36,0)/Assumptions!$B$24,0) -> 631.2928
A37: Mid | B37: =Assumptions!$B$11 -> 500 | C37: =Assumptions!$B$35 -> 1000 | D37: =B37*C37*12 -> 6000000 | E37: =Assumptions!$B$29 -> 0.08 | F37: =D37*E37 -> 480000 | G37: =-(D37*Assumptions!$B$14+IFERROR(D37/Assumptions!$B$13,0)*Assumptions!$B$15) -> -210000 | H37: =-D37*Assumptions!$B$17 -> -60000 | I37: =F37+G37+H37 -> 210000 | J37: =-Costs!D$16 -> -6870.72 | K37: =-Costs!D$18 -> -80000 | L37: =I37+J37+K37 -> 123129.28 | M37: =IF(L37>0,L37*Assumptions!$B$23,L37) -> 61564.64 | N37: =IF(L37>0,L37*(1-Assumptions!$B$23),0) -> 61564.64 | O37: =IFERROR(MAX(M37,0)/Assumptions!$B$24,0) -> 1231.2928
A38: Mid | B38: =Assumptions!$B$11 -> 500 | C38: =Assumptions!$B$35 -> 1000 | D38: =B38*C38*12 -> 6000000 | E38: =Assumptions!$B$30 -> 0.09 | F38: =D38*E38 -> 540000 | G38: =-(D38*Assumptions!$B$14+IFERROR(D38/Assumptions!$B$13,0)*Assumptions!$B$15) -> -210000 | H38: =-D38*Assumptions!$B$17 -> -60000 | I38: =F38+G38+H38 -> 270000 | J38: =-Costs!D$16 -> -6870.72 | K38: =-Costs!D$18 -> -80000 | L38: =I38+J38+K38 -> 183129.28 | M38: =IF(L38>0,L38*Assumptions!$B$23,L38) -> 91564.64 | N38: =IF(L38>0,L38*(1-Assumptions!$B$23),0) -> 91564.64 | O38: =IFERROR(MAX(M38,0)/Assumptions!$B$24,0) -> 1831.2928
A39: Mid | B39: =Assumptions!$B$11 -> 500 | C39: =Assumptions!$B$36 -> 10000 | D39: =B39*C39*12 -> 60000000 | E39: =Assumptions!$B$27 -> 0.06 | F39: =D39*E39 -> 3600000 | G39: =-(D39*Assumptions!$B$14+IFERROR(D39/Assumptions!$B$13,0)*Assumptions!$B$15) -> -2100000 | H39: =-D39*Assumptions!$B$17 -> -600000 | I39: =F39+G39+H39 -> 900000 | J39: =-Costs!E$16 -> -11670.72 | K39: =-Costs!E$18 -> -240000 | L39: =I39+J39+K39 -> 648329.28 | M39: =IF(L39>0,L39*Assumptions!$B$23,L39) -> 324164.64 | N39: =IF(L39>0,L39*(1-Assumptions!$B$23),0) -> 324164.64 | O39: =IFERROR(MAX(M39,0)/Assumptions!$B$24,0) -> 6483.2928
A40: Mid | B40: =Assumptions!$B$11 -> 500 | C40: =Assumptions!$B$36 -> 10000 | D40: =B40*C40*12 -> 60000000 | E40: =Assumptions!$B$28 -> 0.07 | F40: =D40*E40 -> 4200000 | G40: =-(D40*Assumptions!$B$14+IFERROR(D40/Assumptions!$B$13,0)*Assumptions!$B$15) -> -2100000 | H40: =-D40*Assumptions!$B$17 -> -600000 | I40: =F40+G40+H40 -> 1500000 | J40: =-Costs!E$16 -> -11670.72 | K40: =-Costs!E$18 -> -240000 | L40: =I40+J40+K40 -> 1248329.3 | M40: =IF(L40>0,L40*Assumptions!$B$23,L40) -> 624164.64 | N40: =IF(L40>0,L40*(1-Assumptions!$B$23),0) -> 624164.64 | O40: =IFERROR(MAX(M40,0)/Assumptions!$B$24,0) -> 12483.293
A41: Mid | B41: =Assumptions!$B$11 -> 500 | C41: =Assumptions!$B$36 -> 10000 | D41: =B41*C41*12 -> 60000000 | E41: =Assumptions!$B$29 -> 0.08 | F41: =D41*E41 -> 4800000 | G41: =-(D41*Assumptions!$B$14+IFERROR(D41/Assumptions!$B$13,0)*Assumptions!$B$15) -> -2100000 | H41: =-D41*Assumptions!$B$17 -> -600000 | I41: =F41+G41+H41 -> 2100000 | J41: =-Costs!E$16 -> -11670.72 | K41: =-Costs!E$18 -> -240000 | L41: =I41+J41+K41 -> 1848329.3 | M41: =IF(L41>0,L41*Assumptions!$B$23,L41) -> 924164.64 | N41: =IF(L41>0,L41*(1-Assumptions!$B$23),0) -> 924164.64 | O41: =IFERROR(MAX(M41,0)/Assumptions!$B$24,0) -> 18483.293
A42: Mid | B42: =Assumptions!$B$11 -> 500 | C42: =Assumptions!$B$36 -> 10000 | D42: =B42*C42*12 -> 60000000 | E42: =Assumptions!$B$30 -> 0.09 | F42: =D42*E42 -> 5400000 | G42: =-(D42*Assumptions!$B$14+IFERROR(D42/Assumptions!$B$13,0)*Assumptions!$B$15) -> -2100000 | H42: =-D42*Assumptions!$B$17 -> -600000 | I42: =F42+G42+H42 -> 2700000 | J42: =-Costs!E$16 -> -11670.72 | K42: =-Costs!E$18 -> -240000 | L42: =I42+J42+K42 -> 2448329.3 | M42: =IF(L42>0,L42*Assumptions!$B$23,L42) -> 1224164.6 | N42: =IF(L42>0,L42*(1-Assumptions!$B$23),0) -> 1224164.6 | O42: =IFERROR(MAX(M42,0)/Assumptions!$B$24,0) -> 24483.293
A45: HIGH GMV BAND
...

Sheet Sensitivity
A1: Sensitivity — where the model breaks
A3: 1. NET TAKE RATE by fee and loss rate
A4: Fee | B4: =Assumptions!$B$16 -> 0.005 | C4: =Assumptions!$B$17 -> 0.01 | D4: =Assumptions!$B$18 -> 0.02
A5: =Assumptions!$B$27 -> 0.06 | B5: =$A5-Assumptions!$B$14-(Assumptions!$B$15/Assumptions!$B$13)-Assumptions!$B$16 -> 0.02 | C5: =$A5-Assumptions!$B$14-(Assumptions!$B$15/Assumptions!$B$13)-Assumptions!$B$17 -> 0.015 | D5: =$A5-Assumptions!$B$14-(Assumptions!$B$15/Assumptions!$B$13)-Assumptions!$B$18 -> 0.005
A6: =Assumptions!$B$28 -> 0.07 | B6: =$A6-Assumptions!$B$14-(Assumptions!$B$15/Assumptions!$B$13)-Assumptions!$B$16 -> 0.03 | C6: =$A6-Assumptions!$B$14-(Assumptions!$B$15/Assumptions!$B$13)-Assumptions!$B$17 -> 0.025 | D6: =$A6-Assumptions!$B$14-(Assumptions!$B$15/Assumptions!$B$13)-Assumptions!$B$18 -> 0.015
A7: =Assumptions!$B$29 -> 0.08 | B7: =$A7-Assumptions!$B$14-(Assumptions!$B$15/Assumptions!$B$13)-Assumptions!$B$16 -> 0.04 | C7: =$A7-Assumptions!$B$14-(Assumptions!$B$15/Assumptions!$B$13)-Assumptions!$B$17 -> 0.035 | D7: =$A7-Assumptions!$B$14-(Assumptions!$B$15/Assumptions!$B$13)-Assumptions!$B$18 -> 0.025
A8: =Assumptions!$B$30 -> 0.09 | B8: =$A8-Assumptions!$B$14-(Assumptions!$B$15/Assumptions!$B$13)-Assumptions!$B$16 -> 0.05 | C8: =$A8-Assumptions!$B$14-(Assumptions!$B$15/Assumptions!$B$13)-Assumptions!$B$17 -> 0.045 | D8: =$A8-Assumptions!$B$14-(Assumptions!$B$15/Assumptions!$B$13)-Assumptions!$B$18 -> 0.035
A10: A 6% fee at a 2% loss rate nets 0.5%. That combination does not survive at any seller count.
A12: 2. AOV SENSITIVITY (at base loss rate)
A13: AOV | B13: =Assumptions!$B$27 -> 0.06 | C13: =Assumptions!$B$28 -> 0.07 | D13: =Assumptions!$B$29 -> 0.08 | E13: =Assumptions!$B$30 -> 0.09
A14: 10 | B14: =Assumptions!$B$27-Assumptions!$B$14-(Assumptions!$B$15/$A14)-Assumptions!$B$17 -> -0.009 | C14: =Assumptions!$B$28-Assumptions!$B$14-(Assumptions!$B$15/$A14)-Assumptions!$B$17 -> 0.001 | D14: =Assumptions!$B$29-Assumptions!$B$14-(Assumptions!$B$15/$A14)-Assumptions!$B$17 -> 0.011 | E14: =Assumptions!$B$30-Assumptions!$B$14-(Assumptions!$B$15/$A14)-Assumptions!$B$17 -> 0.021
A15: 25 | B15: =Assumptions!$B$27-Assumptions!$B$14-(Assumptions!$B$15/$A15)-Assumptions!$B$17 -> 0.009 | C15: =Assumptions!$B$28-Assumptions!$B$14-(Assumptions!$B$15/$A15)-Assumptions!$B$17 -> 0.019 | D15: =Assumptions!$B$29-Assumptions!$B$14-(Assumptions!$B$15/$A15)-Assumptions!$B$17 -> 0.029 | E15: =Assumptions!$B$30-Assumptions!$B$14-(Assumptions!$B$15/$A15)-Assumptions!$B$17 -> 0.039
A16: 50 | B16: =Assumptions!$B$27-Assumptions!$B$14-(Assumptions!$B$15/$A16)-Assumptions!$B$17 -> 0.015 | C16: =Assumptions!$B$28-Assumptions!$B$14-(Assumptions!$B$15/$A16)-Assumptions!$B$17 -> 0.025 | D16: =Assumptions!$B$29-Assumptions!$B$14-(Assumptions!$B$15/$A16)-Assumptions!$B$17 -> 0.035 | E16: =Assumptions!$B$30-Assumptions!$B$14-(Assumptions!$B$15/$A16)-Assumptions!$B$17 -> 0.045
A17: 100 | B17: =Assumptions!$B$27-Assumptions!$B$14-(Assumptions!$B$15/$A17)-Assumptions!$B$17 -> 0.018 | C17: =Assumptions!$B$28-Assumptions!$B$14-(Assumptions!$B$15/$A17)-Assumptions!$B$17 -> 0.028 | D17: =Assumptions!$B$29-Assumptions!$B$14-(Assumptions!$B$15/$A17)-Assumptions!$B$17 -> 0.038 | E17: =Assumptions!$B$30-Assumptions!$B$14-(Assumptions!$B$15/$A17)-Assumptions!$B$17 -> 0.048
A18: 250 | B18: =Assumptions!$B$27-Assumptions!$B$14-(Assumptions!$B$15/$A18)-Assumptions!$B$17 -> 0.0198 | C18: =Assumptions!$B$28-Assumptions!$B$14-(Assumptions!$B$15/$A18)-Assumptions!$B$17 -> 0.0298 | D18: =Assumptions!$B$29-Assumptions!$B$14-(Assumptions!$B$15/$A18)-Assumptions!$B$17 -> 0.0398 | E18: =Assumptions!$B$30-Assumptions!$B$14-(Assumptions!$B$15/$A18)-Assumptions!$B$17 -> 0.0498
A21: 3. THE HIRING VALLEY — first hire lands at 200 sellers, before the revenue does
A22: At 8%, base loss. 'Recover at' is where profit returns to zero after the salary lands.
A23: GMV band | B23: Breakeven before hire | C23: Hire at | D23: Recover at | E23: Growth needed to recover
A24: Low ($110/mo) | B24: 68 | C24: 200 | D24: 1800 | E24: 9.0x
A25: Mid ($500/mo) | B25: 15 | C25: 200 | D25: 396 | E25: 2.0x
A26: High ($2,000/mo) | B26: 4 | C26: - | D26: - | E26: no valley
A28: In the low band the valley runs 200 -> 1,800 sellers: 9x growth to climb back to breakeven. The difference between hiring at 200 and hiring at 600 is roughly a year of runway.
A31: 4. COMPETITIVE REFERENCE — what a seller pays on a $50 order
A32: Platform / scenario | B32: Seller pays | C32: Source
A33: art-store @ 6% | B33: 0.06 | C33: By construction
A34: art-store @ 7% | B34: 0.07 | C34: By construction
A35: art-store @ 8% | B35: 0.08 | C35: By construction
A36: art-store @ 9% | B36: 0.09 | C36: By construction
A37: Etsy baseline, US seller, no ads | B37: 0.104 | C37: etsy-fees-and-pricing-model.md s5.1 - HIGH
A38: Etsy + Offsite Ads, 12% tier | B38: 0.224 | C38: etsy-fees-and-pricing-model.md s5.2 - HIGH
A39: Etsy + Offsite Ads, 15% tier | B39: 0.254 | C39: etsy-fees-and-pricing-model.md s5.2 - HIGH

Sheet Profit Targets
A1: What Would Have To Be True — Profit Targets
A2: Solves the model backwards. Change the targets in yellow; everything recalculates.
A3: PROFIT BEFORE FOUNDER COMPENSATION. Two founders at $120,000 turns a $300,000 target into $540,000.
A5: COST STEPS APPLIED | B5: Seller range | C5: Software /yr | D5: FTE | E5: Labour /yr | F5: Total fixed /yr
A6: Step 1 | B6: 0 - 199 | C6: 3138.72 | D6: 0 | E6: =D6*Assumptions!$B$19 -> 0 | F6: =C6+E6 -> 3138.72
A7: Step 2 | B7: 200 - 999 | C7: 3138.72 | D7: 1 | E7: =D7*Assumptions!$B$19 -> 80000 | F7: =C7+E7 -> 83138.72
A8: Step 3 | B8: 1,000 - 1,999 | C8: 6870.72 | D8: 1 | E8: =D8*Assumptions!$B$19 -> 80000 | F8: =C8+E8 -> 86870.72
A9: Step 4 | B9: 2,000 - 9,999 | C9: 6870.72 | D9: 2 | E9: =D9*Assumptions!$B$19 -> 160000 | F9: =C9+E9 -> 166870.72
A10: Step 5 | B10: 10,000 and above | C10: 11670.72 | D10: 3 | E10: =D10*Assumptions!$B$19 -> 240000 | F10: =C10+E10 -> 251670.72
A12: PROFIT TARGETS
A13: Target 1 | B13: 100000
A14: Target 2 | B14: 300000
A15: Target 3 | B15: 500000
A17: TABLE A - SELLERS REQUIRED (base loss rate)
A18: Profit target | B18: Fee | C18: Low band | D18: Mid band | E18: High band
A19: =$B$13 -> 100000 | B19: =Assumptions!$B$27 -> 0.06 | C19: =IFERROR(IF((($A19+$F$6)/(Assumptions!$B$10*12*Assumptions!$C$27))<200,ROUNDUP((($A19+$F$6)/(Assumptions!$B$10*12*Assumptions!$C$27)),0),IF((($A19+$F$7)/(Assumptions!$B$10*12*Assumptions!$C$27))<1000,ROUNDUP((($A19+$F$7)/(Assumptions!$B$10*12*Assumptions!$C$27)),0),IF((($A19+$F$8)/(Assumptions!$B$10*12*Assumptions!$C$27))<2000,ROUNDUP((($A19+$F$8)/(Assumptions!$B$10*12*Assumptions!$C$27)),0),IF((($A19+$F$9)/(Assumptions!$B$10*12*Assumptions!$C$27))<10000,ROUNDUP((($A19+$F$9)/(Assumptions!$B$10*12*Assumptions!$C$27)),0),ROUNDUP((($A19+$F$10)/(Assumptions!$B$10*12*Assumptions!$C$27)),0))))),"n/a") -> 17762 | D19: =IFERROR(IF((($A19+$F$6)/(Assumptions!$B$11*12*Assumptions!$C$27))<200,ROUNDUP((($A19+$F$6)/(Assumptions!$B$11*12*Assumptions!$C$27)),0),IF((($A19+$F$7)/(Assumptions!$B$11*12*Assumptions!$C$27))<1000,ROUNDUP((($A19+$F$7)/(Assumptions!$B$11*12*Assumptions!$C$27)),0),IF((($A19+$F$8)/(Assumptions!$B$11*12*Assumptions!$C$27))<2000,ROUNDUP((($A19+$F$8)/(Assumptions!$B$11*12*Assumptions!$C$27)),0),IF((($A19+$F$9)/(Assumptions!$B$11*12*Assumptions!$C$27))<10000,ROUNDUP((($A19+$F$9)/(Assumptions!$B$11*12*Assumptions!$C$27)),0),ROUNDUP((($A19+$F$10)/(Assumptions!$B$11*12*Assumptions!$C$27)),0))))),"n/a") -> 2966 | E19: =IFERROR(IF((($A19+$F$6)/(Assumptions!$B$12*12*Assumptions!$C$27))<200,ROUNDUP((($A19+$F$6)/(Assumptions!$B$12*12*Assumptions!$C$27)),0),IF((($A19+$F$7)/(Assumptions!$B$12*12*Assumptions!$C$27))<1000,ROUNDUP((($A19+$F$7)/(Assumptions!$B$12*12*Assumptions!$C$27)),0),IF((($A19+$F$8)/(Assumptions!$B$12*12*Assumptions!$C$27))<2000,ROUNDUP((($A19+$F$8)/(Assumptions!$B$12*12*Assumptions!$C$27)),0),IF((($A19+$F$9)/(Assumptions!$B$12*12*Assumptions!$C$27))<10000,ROUNDUP((($A19+$F$9)/(Assumptions!$B$12*12*Assumptions!$C$27)),0),ROUNDUP((($A19+$F$10)/(Assumptions!$B$12*12*Assumptions!$C$27)),0))))),"n/a") -> 509
A20: =$B$13 -> 100000 | B20: =Assumptions!$B$28 -> 0.07 | C20: =IFERROR(IF((($A20+$F$6)/(Assumptions!$B$10*12*Assumptions!$C$28))<200,ROUNDUP((($A20+$F$6)/(Assumptions!$B$10*12*Assumptions!$C$28)),0),IF((($A20+$F$7)/(Assumptions!$B$10*12*Assumptions!$C$28))<1000,ROUNDUP((($A20+$F$7)/(Assumptions!$B$10*12*Assumptions!$C$28)),0),IF((($A20+$F$8)/(Assumptions!$B$10*12*Assumptions!$C$28))<2000,ROUNDUP((($A20+$F$8)/(Assumptions!$B$10*12*Assumptions!$C$28)),0),IF((($A20+$F$9)/(Assumptions!$B$10*12*Assumptions!$C$28))<10000,ROUNDUP((($A20+$F$9)/(Assumptions!$B$10*12*Assumptions!$C$28)),0),ROUNDUP((($A20+$F$10)/(Assumptions!$B$10*12*Assumptions!$C$28)),0))))),"n/a") -> 8087 | D20: =IFERROR(IF((($A20+$F$6)/(Assumptions!$B$11*12*Assumptions!$C$28))<200,ROUNDUP((($A20+$F$6)/(Assumptions!$B$11*12*Assumptions!$C$28)),0),IF((($A20+$F$7)/(Assumptions!$B$11*12*Assumptions!$C$28))<1000,ROUNDUP((($A20+$F$7)/(Assumptions!$B$11*12*Assumptions!$C$28)),0),IF((($A20+$F$8)/(Assumptions!$B$11*12*Assumptions!$C$28))<2000,ROUNDUP((($A20+$F$8)/(Assumptions!$B$11*12*Assumptions!$C$28)),0),IF((($A20+$F$9)/(Assumptions!$B$11*12*Assumptions!$C$28))<10000,ROUNDUP((($A20+$F$9)/(Assumptions!$B$11*12*Assumptions!$C$28)),0),ROUNDUP((($A20+$F$10)/(Assumptions!$B$11*12*Assumptions!$C$28)),0))))),"n/a") -> 1246 | E20: =IFERROR(IF((($A20+$F$6)/(Assumptions!$B$12*12*Assumptions!$C$28))<200,ROUNDUP((($A20+$F$6)/(Assumptions!$B$12*12*Assumptions!$C$28)),0),IF((($A20+$F$7)/(Assumptions!$B$12*12*Assumptions!$C$28))<1000,ROUNDUP((($A20+$F$7)/(Assumptions!$B$12*12*Assumptions!$C$28)),0),IF((($A20+$F$8)/(Assumptions!$B$12*12*Assumptions!$C$28))<2000,ROUNDUP((($A20+$F$8)/(Assumptions!$B$12*12*Assumptions!$C$28)),0),IF((($A20+$F$9)/(Assumptions!$B$12*12*Assumptions!$C$28))<10000,ROUNDUP((($A20+$F$9)/(Assumptions!$B$12*12*Assumptions!$C$28)),0),ROUNDUP((($A20+$F$10)/(Assumptions!$B$12*12*Assumptions!$C$28)),0))))),"n/a") -> 172
A21: =$B$13 -> 100000 | B21: =Assumptions!$B$29 -> 0.08 | C21: =IFERROR(IF((($A21+$F$6)/(Assumptions!$B$10*12*Assumptions!$C$29))<200,ROUNDUP((($A21+$F$6)/(Assumptions!$B$10*12*Assumptions!$C$29)),0),IF((($A21+$F$7)/(Assumptions!$B$10*12*Assumptions!$C$29))<1000,ROUNDUP((($A21+$F$7)/(Assumptions!$B$10*12*Assumptions!$C$29)),0),IF((($A21+$F$8)/(Assumptions!$B$10*12*Assumptions!$C$29))<2000,ROUNDUP((($A21+$F$8)/(Assumptions!$B$10*12*Assumptions!$C$29)),0),IF((($A21+$F$9)/(Assumptions!$B$10*12*Assumptions!$C$29))<10000,ROUNDUP((($A21+$F$9)/(Assumptions!$B$10*12*Assumptions!$C$29)),0),ROUNDUP((($A21+$F$10)/(Assumptions!$B$10*12*Assumptions!$C$29)),0))))),"n/a") -> 5777 | D21: =IFERROR(IF((($A21+$F$6)/(Assumptions!$B$11*12*Assumptions!$C$29))<200,ROUNDUP((($A21+$F$6)/(Assumptions!$B$11*12*Assumptions!$C$29)),0),IF((($A21+$F$7)/(Assumptions!$B$11*12*Assumptions!$C$29))<1000,ROUNDUP((($A21+$F$7)/(Assumptions!$B$11*12*Assumptions!$C$29)),0),IF((($A21+$F$8)/(Assumptions!$B$11*12*Assumptions!$C$29))<2000,ROUNDUP((($A21+$F$8)/(Assumptions!$B$11*12*Assumptions!$C$29)),0),IF((($A21+$F$9)/(Assumptions!$B$11*12*Assumptions!$C$29))<10000,ROUNDUP((($A21+$F$9)/(Assumptions!$B$11*12*Assumptions!$C$29)),0),ROUNDUP((($A21+$F$10)/(Assumptions!$B$11*12*Assumptions!$C$29)),0))))),"n/a") -> 873 | E21: =IFERROR(IF((($A21+$F$6)/(Assumptions!$B$12*12*Assumptions!$C$29))<200,ROUNDUP((($A21+$F$6)/(Assumptions!$B$12*12*Assumptions!$C$29)),0),IF((($A21+$F$7)/(Assumptions!$B$12*12*Assumptions!$C$29))<1000,ROUNDUP((($A21+$F$7)/(Assumptions!$B$12*12*Assumptions!$C$29)),0),IF((($A21+$F$8)/(Assumptions!$B$12*12*Assumptions!$C$29))<2000,ROUNDUP((($A21+$F$8)/(Assumptions!$B$12*12*Assumptions!$C$29)),0),IF((($A21+$F$9)/(Assumptions!$B$12*12*Assumptions!$C$29))<10000,ROUNDUP((($A21+$F$9)/(Assumptions!$B$12*12*Assumptions!$C$29)),0),ROUNDUP((($A21+$F$10)/(Assumptions!$B$12*12*Assumptions!$C$29)),0))))),"n/a") -> 123
A22: =$B$13 -> 100000 | B22: =Assumptions!$B$30 -> 0.09 | C22: =IFERROR(IF((($A22+$F$6)/(Assumptions!$B$10*12*Assumptions!$C$30))<200,ROUNDUP((($A22+$F$6)/(Assumptions!$B$10*12*Assumptions!$C$30)),0),IF((($A22+$F$7)/(Assumptions!$B$10*12*Assumptions!$C$30))<1000,ROUNDUP((($A22+$F$7)/(Assumptions!$B$10*12*Assumptions!$C$30)),0),IF((($A22+$F$8)/(Assumptions!$B$10*12*Assumptions!$C$30))<2000,ROUNDUP((($A22+$F$8)/(Assumptions!$B$10*12*Assumptions!$C$30)),0),IF((($A22+$F$9)/(Assumptions!$B$10*12*Assumptions!$C$30))<10000,ROUNDUP((($A22+$F$9)/(Assumptions!$B$10*12*Assumptions!$C$30)),0),ROUNDUP((($A22+$F$10)/(Assumptions!$B$10*12*Assumptions!$C$30)),0))))),"n/a") -> 4493 | D22: =IFERROR(IF((($A22+$F$6)/(Assumptions!$B$11*12*Assumptions!$C$30))<200,ROUNDUP((($A22+$F$6)/(Assumptions!$B$11*12*Assumptions!$C$30)),0),IF((($A22+$F$7)/(Assumptions!$B$11*12*Assumptions!$C$30))<1000,ROUNDUP((($A22+$F$7)/(Assumptions!$B$11*12*Assumptions!$C$30)),0),IF((($A22+$F$8)/(Assumptions!$B$11*12*Assumptions!$C$30))<2000,ROUNDUP((($A22+$F$8)/(Assumptions!$B$11*12*Assumptions!$C$30)),0),IF((($A22+$F$9)/(Assumptions!$B$11*12*Assumptions!$C$30))<10000,ROUNDUP((($A22+$F$9)/(Assumptions!$B$11*12*Assumptions!$C$30)),0),ROUNDUP((($A22+$F$10)/(Assumptions!$B$11*12*Assumptions!$C$30)),0))))),"n/a") -> 679 | E22: =IFERROR(IF((($A22+$F$6)/(Assumptions!$B$12*12*Assumptions!$C$30))<200,ROUNDUP((($A22+$F$6)/(Assumptions!$B$12*12*Assumptions!$C$30)),0),IF((($A22+$F$7)/(Assumptions!$B$12*12*Assumptions!$C$30))<1000,ROUNDUP((($A22+$F$7)/(Assumptions!$B$12*12*Assumptions!$C$30)),0),IF((($A22+$F$8)/(Assumptions!$B$12*12*Assumptions!$C$30))<2000,ROUNDUP((($A22+$F$8)/(Assumptions!$B$12*12*Assumptions!$C$30)),0),IF((($A22+$F$9)/(Assumptions!$B$12*12*Assumptions!$C$30))<10000,ROUNDUP((($A22+$F$9)/(Assumptions!$B$12*12*Assumptions!$C$30)),0),ROUNDUP((($A22+$F$10)/(Assumptions!$B$12*12*Assumptions!$C$30)),0))))),"n/a") -> 96
A23: =$B$14 -> 300000 | B23: =Assumptions!$B$27 -> 0.06 | C23: =IFERROR(IF((($A23+$F$6)/(Assumptions!$B$10*12*Assumptions!$C$27))<200,ROUNDUP((($A23+$F$6)/(Assumptions!$B$10*12*Assumptions!$C$27)),0),IF((($A23+$F$7)/(Assumptions!$B$10*12*Assumptions!$C$27))<1000,ROUNDUP((($A23+$F$7)/(Assumptions!$B$10*12*Assumptions!$C$27)),0),IF((($A23+$F$8)/(Assumptions!$B$10*12*Assumptions!$C$27))<2000,ROUNDUP((($A23+$F$8)/(Assumptions!$B$10*12*Assumptions!$C$27)),0),IF((($A23+$F$9)/(Assumptions!$B$10*12*Assumptions!$C$27))<10000,ROUNDUP((($A23+$F$9)/(Assumptions!$B$10*12*Assumptions!$C$27)),0),ROUNDUP((($A23+$F$10)/(Assumptions!$B$10*12*Assumptions!$C$27)),0))))),"n/a") -> 27863 | D23: =IFERROR(IF((($A23+$F$6)/(Assumptions!$B$11*12*Assumptions!$C$27))<200,ROUNDUP((($A23+$F$6)/(Assumptions!$B$11*12*Assumptions!$C$27)),0),IF((($A23+$F$7)/(Assumptions!$B$11*12*Assumptions!$C$27))<1000,ROUNDUP((($A23+$F$7)/(Assumptions!$B$11*12*Assumptions!$C$27)),0),IF((($A23+$F$8)/(Assumptions!$B$11*12*Assumptions!$C$27))<2000,ROUNDUP((($A23+$F$8)/(Assumptions!$B$11*12*Assumptions!$C$27)),0),IF((($A23+$F$9)/(Assumptions!$B$11*12*Assumptions!$C$27))<10000,ROUNDUP((($A23+$F$9)/(Assumptions!$B$11*12*Assumptions!$C$27)),0),ROUNDUP((($A23+$F$10)/(Assumptions!$B$11*12*Assumptions!$C$27)),0))))),"n/a") -> 5188 | E23: =IFERROR(IF((($A23+$F$6)/(Assumptions!$B$12*12*Assumptions!$C$27))<200,ROUNDUP((($A23+$F$6)/(Assumptions!$B$12*12*Assumptions!$C$27)),0),IF((($A23+$F$7)/(Assumptions!$B$12*12*Assumptions!$C$27))<1000,ROUNDUP((($A23+$F$7)/(Assumptions!$B$12*12*Assumptions!$C$27)),0),IF((($A23+$F$8)/(Assumptions!$B$12*12*Assumptions!$C$27))<2000,ROUNDUP((($A23+$F$8)/(Assumptions!$B$12*12*Assumptions!$C$27)),0),IF((($A23+$F$9)/(Assumptions!$B$12*12*Assumptions!$C$27))<10000,ROUNDUP((($A23+$F$9)/(Assumptions!$B$12*12*Assumptions!$C$27)),0),ROUNDUP((($A23+$F$10)/(Assumptions!$B$12*12*Assumptions!$C$27)),0))))),"n/a") -> 1075
A24: =$B$14 -> 300000 | B24: =Assumptions!$B$28 -> 0.07 | C24: =IFERROR(IF((($A24+$F$6)/(Assumptions!$B$10*12*Assumptions!$C$28))<200,ROUNDUP((($A24+$F$6)/(Assumptions!$B$10*12*Assumptions!$C$28)),0),IF((($A24+$F$7)/(Assumptions!$B$10*12*Assumptions!$C$28))<1000,ROUNDUP((($A24+$F$7)/(Assumptions!$B$10*12*Assumptions!$C$28)),0),IF((($A24+$F$8)/(Assumptions!$B$10*12*Assumptions!$C$28))<2000,ROUNDUP((($A24+$F$8)/(Assumptions!$B$10*12*Assumptions!$C$28)),0),IF((($A24+$F$9)/(Assumptions!$B$10*12*Assumptions!$C$28))<10000,ROUNDUP((($A24+$F$9)/(Assumptions!$B$10*12*Assumptions!$C$28)),0),ROUNDUP((($A24+$F$10)/(Assumptions!$B$10*12*Assumptions!$C$28)),0))))),"n/a") -> 16718 | D24: =IFERROR(IF((($A24+$F$6)/(Assumptions!$B$11*12*Assumptions!$C$28))<200,ROUNDUP((($A24+$F$6)/(Assumptions!$B$11*12*Assumptions!$C$28)),0),IF((($A24+$F$7)/(Assumptions!$B$11*12*Assumptions!$C$28))<1000,ROUNDUP((($A24+$F$7)/(Assumptions!$B$11*12*Assumptions!$C$28)),0),IF((($A24+$F$8)/(Assumptions!$B$11*12*Assumptions!$C$28))<2000,ROUNDUP((($A24+$F$8)/(Assumptions!$B$11*12*Assumptions!$C$28)),0),IF((($A24+$F$9)/(Assumptions!$B$11*12*Assumptions!$C$28))<10000,ROUNDUP((($A24+$F$9)/(Assumptions!$B$11*12*Assumptions!$C$28)),0),ROUNDUP((($A24+$F$10)/(Assumptions!$B$11*12*Assumptions!$C$28)),0))))),"n/a") -> 3113 | E24: =IFERROR(IF((($A24+$F$6)/(Assumptions!$B$12*12*Assumptions!$C$28))<200,ROUNDUP((($A24+$F$6)/(Assumptions!$B$12*12*Assumptions!$C$28)),0),IF((($A24+$F$7)/(Assumptions!$B$12*12*Assumptions!$C$28))<1000,ROUNDUP((($A24+$F$7)/(Assumptions!$B$12*12*Assumptions!$C$28)),0),IF((($A24+$F$8)/(Assumptions!$B$12*12*Assumptions!$C$28))<2000,ROUNDUP((($A24+$F$8)/(Assumptions!$B$12*12*Assumptions!$C$28)),0),IF((($A24+$F$9)/(Assumptions!$B$12*12*Assumptions!$C$28))<10000,ROUNDUP((($A24+$F$9)/(Assumptions!$B$12*12*Assumptions!$C$28)),0),ROUNDUP((($A24+$F$10)/(Assumptions!$B$12*12*Assumptions!$C$28)),0))))),"n/a") -> 639
A25: =$B$14 -> 300000 | B25: =Assumptions!$B$29 -> 0.08 | C25: =IFERROR(IF((($A25+$F$6)/(Assumptions!$B$10*12*Assumptions!$C$29))<200,ROUNDUP((($A25+$F$6)/(Assumptions!$B$10*12*Assumptions!$C$29)),0),IF((($A25+$F$7)/(Assumptions!$B$10*12*Assumptions!$C$29))<1000,ROUNDUP((($A25+$F$7)/(Assumptions!$B$10*12*Assumptions!$C$29)),0),IF((($A25+$F$8)/(Assumptions!$B$10*12*Assumptions!$C$29))<2000,ROUNDUP((($A25+$F$8)/(Assumptions!$B$10*12*Assumptions!$C$29)),0),IF((($A25+$F$9)/(Assumptions!$B$10*12*Assumptions!$C$29))<10000,ROUNDUP((($A25+$F$9)/(Assumptions!$B$10*12*Assumptions!$C$29)),0),ROUNDUP((($A25+$F$10)/(Assumptions!$B$10*12*Assumptions!$C$29)),0))))),"n/a") -> 11941 | D25: =IFERROR(IF((($A25+$F$6)/(Assumptions!$B$11*12*Assumptions!$C$29))<200,ROUNDUP((($A25+$F$6)/(Assumptions!$B$11*12*Assumptions!$C$29)),0),IF((($A25+$F$7)/(Assumptions!$B$11*12*Assumptions!$C$29))<1000,ROUNDUP((($A25+$F$7)/(Assumptions!$B$11*12*Assumptions!$C$29)),0),IF((($A25+$F$8)/(Assumptions!$B$11*12*Assumptions!$C$29))<2000,ROUNDUP((($A25+$F$8)/(Assumptions!$B$11*12*Assumptions!$C$29)),0),IF((($A25+$F$9)/(Assumptions!$B$11*12*Assumptions!$C$29))<10000,ROUNDUP((($A25+$F$9)/(Assumptions!$B$11*12*Assumptions!$C$29)),0),ROUNDUP((($A25+$F$10)/(Assumptions!$B$11*12*Assumptions!$C$29)),0))))),"n/a") -> 1843 | E25: =IFERROR(IF((($A25+$F$6)/(Assumptions!$B$12*12*Assumptions!$C$29))<200,ROUNDUP((($A25+$F$6)/(Assumptions!$B$12*12*Assumptions!$C$29)),0),IF((($A25+$F$7)/(Assumptions!$B$12*12*Assumptions!$C$29))<1000,ROUNDUP((($A25+$F$7)/(Assumptions!$B$12*12*Assumptions!$C$29)),0),IF((($A25+$F$8)/(Assumptions!$B$12*12*Assumptions!$C$29))<2000,ROUNDUP((($A25+$F$8)/(Assumptions!$B$12*12*Assumptions!$C$29)),0),IF((($A25+$F$9)/(Assumptions!$B$12*12*Assumptions!$C$29))<10000,ROUNDUP((($A25+$F$9)/(Assumptions!$B$12*12*Assumptions!$C$29)),0),ROUNDUP((($A25+$F$10)/(Assumptions!$B$12*12*Assumptions!$C$29)),0))))),"n/a") -> 457
A26: =$B$14 -> 300000 | B26: =Assumptions!$B$30 -> 0.09 | C26: =IFERROR(IF((($A26+$F$6)/(Assumptions!$B$10*12*Assumptions!$C$30))<200,ROUNDUP((($A26+$F$6)/(Assumptions!$B$10*12*Assumptions!$C$30)),0),IF((($A26+$F$7)/(Assumptions!$B$10*12*Assumptions!$C$30))<1000,ROUNDUP((($A26+$F$7)/(Assumptions!$B$10*12*Assumptions!$C$30)),0),IF((($A26+$F$8)/(Assumptions!$B$10*12*Assumptions!$C$30))<2000,ROUNDUP((($A26+$F$8)/(Assumptions!$B$10*12*Assumptions!$C$30)),0),IF((($A26+$F$9)/(Assumptions!$B$10*12*Assumptions!$C$30))<10000,ROUNDUP((($A26+$F$9)/(Assumptions!$B$10*12*Assumptions!$C$30)),0),ROUNDUP((($A26+$F$10)/(Assumptions!$B$10*12*Assumptions!$C$30)),0))))),"n/a") -> 7860 | D26: =IFERROR(IF((($A26+$F$6)/(Assumptions!$B$11*12*Assumptions!$C$30))<200,ROUNDUP((($A26+$F$6)/(Assumptions!$B$11*12*Assumptions!$C$30)),0),IF((($A26+$F$7)/(Assumptions!$B$11*12*Assumptions!$C$30))<1000,ROUNDUP((($A26+$F$7)/(Assumptions!$B$11*12*Assumptions!$C$30)),0),IF((($A26+$F$8)/(Assumptions!$B$11*12*Assumptions!$C$30))<2000,ROUNDUP((($A26+$F$8)/(Assumptions!$B$11*12*Assumptions!$C$30)),0),IF((($A26+$F$9)/(Assumptions!$B$11*12*Assumptions!$C$30))<10000,ROUNDUP((($A26+$F$9)/(Assumptions!$B$11*12*Assumptions!$C$30)),0),ROUNDUP((($A26+$F$10)/(Assumptions!$B$11*12*Assumptions!$C$30)),0))))),"n/a") -> 1433 | E26: =IFERROR(IF((($A26+$F$6)/(Assumptions!$B$12*12*Assumptions!$C$30))<200,ROUNDUP((($A26+$F$6)/(Assumptions!$B$12*12*Assumptions!$C$30)),0),IF((($A26+$F$7)/(Assumptions!$B$12*12*Assumptions!$C$30))<1000,ROUNDUP((($A26+$F$7)/(Assumptions!$B$12*12*Assumptions!$C$30)),0),IF((($A26+$F$8)/(Assumptions!$B$12*12*Assumptions!$C$30))<2000,ROUNDUP((($A26+$F$8)/(Assumptions!$B$12*12*Assumptions!$C$30)),0),IF((($A26+$F$9)/(Assumptions!$B$12*12*Assumptions!$C$30))<10000,ROUNDUP((($A26+$F$9)/(Assumptions!$B$12*12*Assumptions!$C$30)),0),ROUNDUP((($A26+$F$10)/(Assumptions!$B$12*12*Assumptions!$C$30)),0))))),"n/a") -> 355
A27: =$B$15 -> 500000 | B27: =Assumptions!$B$27 -> 0.06 | C27: =IFERROR(IF((($A27+$F$6)/(Assumptions!$B$10*12*Assumptions!$C$27))<200,ROUNDUP((($A27+$F$6)/(Assumptions!$B$10*12*Assumptions!$C$27)),0),IF((($A27+$F$7)/(Assumptions!$B$10*12*Assumptions!$C$27))<1000,ROUNDUP((($A27+$F$7)/(Assumptions!$B$10*12*Assumptions!$C$27)),0),IF((($A27+$F$8)/(Assumptions!$B$10*12*Assumptions!$C$27))<2000,ROUNDUP((($A27+$F$8)/(Assumptions!$B$10*12*Assumptions!$C$27)),0),IF((($A27+$F$9)/(Assumptions!$B$10*12*Assumptions!$C$27))<10000,ROUNDUP((($A27+$F$9)/(Assumptions!$B$10*12*Assumptions!$C$27)),0),ROUNDUP((($A27+$F$10)/(Assumptions!$B$10*12*Assumptions!$C$27)),0))))),"n/a") -> 37964 | D27: =IFERROR(IF((($A27+$F$6)/(Assumptions!$B$11*12*Assumptions!$C$27))<200,ROUNDUP((($A27+$F$6)/(Assumptions!$B$11*12*Assumptions!$C$27)),0),IF((($A27+$F$7)/(Assumptions!$B$11*12*Assumptions!$C$27))<1000,ROUNDUP((($A27+$F$7)/(Assumptions!$B$11*12*Assumptions!$C$27)),0),IF((($A27+$F$8)/(Assumptions!$B$11*12*Assumptions!$C$27))<2000,ROUNDUP((($A27+$F$8)/(Assumptions!$B$11*12*Assumptions!$C$27)),0),IF((($A27+$F$9)/(Assumptions!$B$11*12*Assumptions!$C$27))<10000,ROUNDUP((($A27+$F$9)/(Assumptions!$B$11*12*Assumptions!$C$27)),0),ROUNDUP((($A27+$F$10)/(Assumptions!$B$11*12*Assumptions!$C$27)),0))))),"n/a") -> 7410 | E27: =IFERROR(IF((($A27+$F$6)/(Assumptions!$B$12*12*Assumptions!$C$27))<200,ROUNDUP((($A27+$F$6)/(Assumptions!$B$12*12*Assumptions!$C$27)),0),IF((($A27+$F$7)/(Assumptions!$B$12*12*Assumptions!$C$27))<1000,ROUNDUP((($A27+$F$7)/(Assumptions!$B$12*12*Assumptions!$C$27)),0),IF((($A27+$F$8)/(Assumptions!$B$12*12*Assumptions!$C$27))<2000,ROUNDUP((($A27+$F$8)/(Assumptions!$B$12*12*Assumptions!$C$27)),0),IF((($A27+$F$9)/(Assumptions!$B$12*12*Assumptions!$C$27))<10000,ROUNDUP((($A27+$F$9)/(Assumptions!$B$12*12*Assumptions!$C$27)),0),ROUNDUP((($A27+$F$10)/(Assumptions!$B$12*12*Assumptions!$C$27)),0))))),"n/a") -> 1631
A28: =$B$15 -> 500000 | B28: =Assumptions!$B$28 -> 0.07 | C28: =IFERROR(IF((($A28+$F$6)/(Assumptions!$B$10*12*Assumptions!$C$28))<200,ROUNDUP((($A28+$F$6)/(Assumptions!$B$10*12*Assumptions!$C$28)),0),IF((($A28+$F$7)/(Assumptions!$B$10*12*Assumptions!$C$28))<1000,ROUNDUP((($A28+$F$7)/(Assumptions!$B$10*12*Assumptions!$C$28)),0),IF((($A28+$F$8)/(Assumptions!$B$10*12*Assumptions!$C$28))<2000,ROUNDUP((($A28+$F$8)/(Assumptions!$B$10*12*Assumptions!$C$28)),0),IF((($A28+$F$9)/(Assumptions!$B$10*12*Assumptions!$C$28))<10000,ROUNDUP((($A28+$F$9)/(Assumptions!$B$10*12*Assumptions!$C$28)),0),ROUNDUP((($A28+$F$10)/(Assumptions!$B$10*12*Assumptions!$C$28)),0))))),"n/a") -> 22778 | D28: =IFERROR(IF((($A28+$F$6)/(Assumptions!$B$11*12*Assumptions!$C$28))<200,ROUNDUP((($A28+$F$6)/(Assumptions!$B$11*12*Assumptions!$C$28)),0),IF((($A28+$F$7)/(Assumptions!$B$11*12*Assumptions!$C$28))<1000,ROUNDUP((($A28+$F$7)/(Assumptions!$B$11*12*Assumptions!$C$28)),0),IF((($A28+$F$8)/(Assumptions!$B$11*12*Assumptions!$C$28))<2000,ROUNDUP((($A28+$F$8)/(Assumptions!$B$11*12*Assumptions!$C$28)),0),IF((($A28+$F$9)/(Assumptions!$B$11*12*Assumptions!$C$28))<10000,ROUNDUP((($A28+$F$9)/(Assumptions!$B$11*12*Assumptions!$C$28)),0),ROUNDUP((($A28+$F$10)/(Assumptions!$B$11*12*Assumptions!$C$28)),0))))),"n/a") -> 4446 | E28: =IFERROR(IF((($A28+$F$6)/(Assumptions!$B$12*12*Assumptions!$C$28))<200,ROUNDUP((($A28+$F$6)/(Assumptions!$B$12*12*Assumptions!$C$28)),0),IF((($A28+$F$7)/(Assumptions!$B$12*12*Assumptions!$C$28))<1000,ROUNDUP((($A28+$F$7)/(Assumptions!$B$12*12*Assumptions!$C$28)),0),IF((($A28+$F$8)/(Assumptions!$B$12*12*Assumptions!$C$28))<2000,ROUNDUP((($A28+$F$8)/(Assumptions!$B$12*12*Assumptions!$C$28)),0),IF((($A28+$F$9)/(Assumptions!$B$12*12*Assumptions!$C$28))<10000,ROUNDUP((($A28+$F$9)/(Assumptions!$B$12*12*Assumptions!$C$28)),0),ROUNDUP((($A28+$F$10)/(Assumptions!$B$12*12*Assumptions!$C$28)),0))))),"n/a") -> 972
A29: =$B$15 -> 500000 | B29: =Assumptions!$B$29 -> 0.08 | C29: =IFERROR(IF((($A29+$F$6)/(Assumptions!$B$10*12*Assumptions!$C$29))<200,ROUNDUP((($A29+$F$6)/(Assumptions!$B$10*12*Assumptions!$C$29)),0),IF((($A29+$F$7)/(Assumptions!$B$10*12*Assumptions!$C$29))<1000,ROUNDUP((($A29+$F$7)/(Assumptions!$B$10*12*Assumptions!$C$29)),0),IF((($A29+$F$8)/(Assumptions!$B$10*12*Assumptions!$C$29))<2000,ROUNDUP((($A29+$F$8)/(Assumptions!$B$10*12*Assumptions!$C$29)),0),IF((($A29+$F$9)/(Assumptions!$B$10*12*Assumptions!$C$29))<10000,ROUNDUP((($A29+$F$9)/(Assumptions!$B$10*12*Assumptions!$C$29)),0),ROUNDUP((($A29+$F$10)/(Assumptions!$B$10*12*Assumptions!$C$29)),0))))),"n/a") -> 16270 | D29: =IFERROR(IF((($A29+$F$6)/(Assumptions!$B$11*12*Assumptions!$C$29))<200,ROUNDUP((($A29+$F$6)/(Assumptions!$B$11*12*Assumptions!$C$29)),0),IF((($A29+$F$7)/(Assumptions!$B$11*12*Assumptions!$C$29))<1000,ROUNDUP((($A29+$F$7)/(Assumptions!$B$11*12*Assumptions!$C$29)),0),IF((($A29+$F$8)/(Assumptions!$B$11*12*Assumptions!$C$29))<2000,ROUNDUP((($A29+$F$8)/(Assumptions!$B$11*12*Assumptions!$C$29)),0),IF((($A29+$F$9)/(Assumptions!$B$11*12*Assumptions!$C$29))<10000,ROUNDUP((($A29+$F$9)/(Assumptions!$B$11*12*Assumptions!$C$29)),0),ROUNDUP((($A29+$F$10)/(Assumptions!$B$11*12*Assumptions!$C$29)),0))))),"n/a") -> 3176 | E29: =IFERROR(IF((($A29+$F$6)/(Assumptions!$B$12*12*Assumptions!$C$29))<200,ROUNDUP((($A29+$F$6)/(Assumptions!$B$12*12*Assumptions!$C$29)),0),IF((($A29+$F$7)/(Assumptions!$B$12*12*Assumptions!$C$29))<1000,ROUNDUP((($A29+$F$7)/(Assumptions!$B$12*12*Assumptions!$C$29)),0),IF((($A29+$F$8)/(Assumptions!$B$12*12*Assumptions!$C$29))<2000,ROUNDUP((($A29+$F$8)/(Assumptions!$B$12*12*Assumptions!$C$29)),0),IF((($A29+$F$9)/(Assumptions!$B$12*12*Assumptions!$C$29))<10000,ROUNDUP((($A29+$F$9)/(Assumptions!$B$12*12*Assumptions!$C$29)),0),ROUNDUP((($A29+$F$10)/(Assumptions!$B$12*12*Assumptions!$C$29)),0))))),"n/a") -> 695
A30: =$B$15 -> 500000 | B30: =Assumptions!$B$30 -> 0.09 | C30: =IFERROR(IF((($A30+$F$6)/(Assumptions!$B$10*12*Assumptions!$C$30))<200,ROUNDUP((($A30+$F$6)/(Assumptions!$B$10*12*Assumptions!$C$30)),0),IF((($A30+$F$7)/(Assumptions!$B$10*12*Assumptions!$C$30))<1000,ROUNDUP((($A30+$F$7)/(Assumptions!$B$10*12*Assumptions!$C$30)),0),IF((($A30+$F$8)/(Assumptions!$B$10*12*Assumptions!$C$30))<2000,ROUNDUP((($A30+$F$8)/(Assumptions!$B$10*12*Assumptions!$C$30)),0),IF((($A30+$F$9)/(Assumptions!$B$10*12*Assumptions!$C$30))<10000,ROUNDUP((($A30+$F$9)/(Assumptions!$B$10*12*Assumptions!$C$30)),0),ROUNDUP((($A30+$F$10)/(Assumptions!$B$10*12*Assumptions!$C$30)),0))))),"n/a") -> 12655 | D30: =IFERROR(IF((($A30+$F$6)/(Assumptions!$B$11*12*Assumptions!$C$30))<200,ROUNDUP((($A30+$F$6)/(Assumptions!$B$11*12*Assumptions!$C$30)),0),IF((($A30+$F$7)/(Assumptions!$B$11*12*Assumptions!$C$30))<1000,ROUNDUP((($A30+$F$7)/(Assumptions!$B$11*12*Assumptions!$C$30)),0),IF((($A30+$F$8)/(Assumptions!$B$11*12*Assumptions!$C$30))<2000,ROUNDUP((($A30+$F$8)/(Assumptions!$B$11*12*Assumptions!$C$30)),0),IF((($A30+$F$9)/(Assumptions!$B$11*12*Assumptions!$C$30))<10000,ROUNDUP((($A30+$F$9)/(Assumptions!$B$11*12*Assumptions!$C$30)),0),ROUNDUP((($A30+$F$10)/(Assumptions!$B$11*12*Assumptions!$C$30)),0))))),"n/a") -> 2470 | E30: =IFERROR(IF((($A30+$F$6)/(Assumptions!$B$12*12*Assumptions!$C$30))<200,ROUNDUP((($A30+$F$6)/(Assumptions!$B$12*12*Assumptions!$C$30)),0),IF((($A30+$F$7)/(Assumptions!$B$12*12*Assumptions!$C$30))<1000,ROUNDUP((($A30+$F$7)/(Assumptions!$B$12*12*Assumptions!$C$30)),0),IF((($A30+$F$8)/(Assumptions!$B$12*12*Assumptions!$C$30))<2000,ROUNDUP((($A30+$F$8)/(Assumptions!$B$12*12*Assumptions!$C$30)),0),IF((($A30+$F$9)/(Assumptions!$B$12*12*Assumptions!$C$30))<10000,ROUNDUP((($A30+$F$9)/(Assumptions!$B$12*12*Assumptions!$C$30)),0),ROUNDUP((($A30+$F$10)/(Assumptions!$B$12*12*Assumptions!$C$30)),0))))),"n/a") -> 540
A32: Jumps between fee tiers are hiring steps. A fee cut that pushes you past a hire threshold costs an $80,000 salary, not just the fee points.
A35: TABLE B - MONTHLY GMV PER SELLER REQUIRED, at fixed seller counts
A36: Profit target | B36: Fee | C36: 10 sellers | D36: 100 sellers | E36: 1,000 sellers | F36: 10,000 sellers
A37: =$B$13 -> 100000 | B37: =Assumptions!$B$27 -> 0.06 | C37: =IFERROR(($A37+$F$6)/(Assumptions!$B$33*12*Assumptions!$C$27),0) -> 57299.289 | D37: =IFERROR(($A37+$F$6)/(Assumptions!$B$34*12*Assumptions!$C$27),0) -> 5729.9289 | E37: =IFERROR(($A37+$F$8)/(Assumptions!$B$35*12*Assumptions!$C$27),0) -> 1038.1707 | F37: =IFERROR(($A37+$F$10)/(Assumptions!$B$36*12*Assumptions!$C$27),0) -> 195.37262
A38: =$B$13 -> 100000 | B38: =Assumptions!$B$28 -> 0.07 | C38: =IFERROR(($A38+$F$6)/(Assumptions!$B$33*12*Assumptions!$C$28),0) -> 34379.573 | D38: =IFERROR(($A38+$F$6)/(Assumptions!$B$34*12*Assumptions!$C$28),0) -> 3437.9573 | E38: =IFERROR(($A38+$F$8)/(Assumptions!$B$35*12*Assumptions!$C$28),0) -> 622.9024 | F38: =IFERROR(($A38+$F$10)/(Assumptions!$B$36*12*Assumptions!$C$28),0) -> 117.22357
A39: =$B$13 -> 100000 | B39: =Assumptions!$B$29 -> 0.08 | C39: =IFERROR(($A39+$F$6)/(Assumptions!$B$33*12*Assumptions!$C$29),0) -> 24556.838 | D39: =IFERROR(($A39+$F$6)/(Assumptions!$B$34*12*Assumptions!$C$29),0) -> 2455.6838 | E39: =IFERROR(($A39+$F$8)/(Assumptions!$B$35*12*Assumptions!$C$29),0) -> 444.93029 | F39: =IFERROR(($A39+$F$10)/(Assumptions!$B$36*12*Assumptions!$C$29),0) -> 83.731124
A40: =$B$13 -> 100000 | B40: =Assumptions!$B$30 -> 0.09 | C40: =IFERROR(($A40+$F$6)/(Assumptions!$B$33*12*Assumptions!$C$30),0) -> 19099.763 | D40: =IFERROR(($A40+$F$6)/(Assumptions!$B$34*12*Assumptions!$C$30),0) -> 1909.9763 | E40: =IFERROR(($A40+$F$8)/(Assumptions!$B$35*12*Assumptions!$C$30),0) -> 346.05689 | F40: =IFERROR(($A40+$F$10)/(Assumptions!$B$36*12*Assumptions!$C$30),0) -> 65.124207
A41: =$B$14 -> 300000 | B41: =Assumptions!$B$27 -> 0.06 | C41: =IFERROR(($A41+$F$6)/(Assumptions!$B$33*12*Assumptions!$C$27),0) -> 168410.4 | D41: =IFERROR(($A41+$F$6)/(Assumptions!$B$34*12*Assumptions!$C$27),0) -> 16841.04 | E41: =IFERROR(($A41+$F$8)/(Assumptions!$B$35*12*Assumptions!$C$27),0) -> 2149.2818 | F41: =IFERROR(($A41+$F$10)/(Assumptions!$B$36*12*Assumptions!$C$27),0) -> 306.48373
A42: =$B$14 -> 300000 | B42: =Assumptions!$B$28 -> 0.07 | C42: =IFERROR(($A42+$F$6)/(Assumptions!$B$33*12*Assumptions!$C$28),0) -> 101046.24 | D42: =IFERROR(($A42+$F$6)/(Assumptions!$B$34*12*Assumptions!$C$28),0) -> 10104.624 | E42: =IFERROR(($A42+$F$8)/(Assumptions!$B$35*12*Assumptions!$C$28),0) -> 1289.5691 | F42: =IFERROR(($A42+$F$10)/(Assumptions!$B$36*12*Assumptions!$C$28),0) -> 183.89024
A43: =$B$14 -> 300000 | B43: =Assumptions!$B$29 -> 0.08 | C43: =IFERROR(($A43+$F$6)/(Assumptions!$B$33*12*Assumptions!$C$29),0) -> 72175.886 | D43: =IFERROR(($A43+$F$6)/(Assumptions!$B$34*12*Assumptions!$C$29),0) -> 7217.5886 | E43: =IFERROR(($A43+$F$8)/(Assumptions!$B$35*12*Assumptions!$C$29),0) -> 921.12076 | F43: =IFERROR(($A43+$F$10)/(Assumptions!$B$36*12*Assumptions!$C$29),0) -> 131.35017
A44: =$B$14 -> 300000 | B44: =Assumptions!$B$30 -> 0.09 | C44: =IFERROR(($A44+$F$6)/(Assumptions!$B$33*12*Assumptions!$C$30),0) -> 56136.8 | D44: =IFERROR(($A44+$F$6)/(Assumptions!$B$34*12*Assumptions!$C$30),0) -> 5613.68 | E44: =IFERROR(($A44+$F$8)/(Assumptions!$B$35*12*Assumptions!$C$30),0) -> 716.42726 | F44: =IFERROR(($A44+$F$10)/(Assumptions!$B$36*12*Assumptions!$C$30),0) -> 102.16124
A45: =$B$15 -> 500000 | B45: =Assumptions!$B$27 -> 0.06 | C45: =IFERROR(($A45+$F$6)/(Assumptions!$B$33*12*Assumptions!$C$27),0) -> 279521.51 | D45: =IFERROR(($A45+$F$6)/(Assumptions!$B$34*12*Assumptions!$C$27),0) -> 27952.151 | E45: =IFERROR(($A45+$F$8)/(Assumptions!$B$35*12*Assumptions!$C$27),0) -> 3260.3929 | F45: =IFERROR(($A45+$F$10)/(Assumptions!$B$36*12*Assumptions!$C$27),0) -> 417.59484
A46: =$B$15 -> 500000 | B46: =Assumptions!$B$28 -> 0.07 | C46: =IFERROR(($A46+$F$6)/(Assumptions!$B$33*12*Assumptions!$C$28),0) -> 167712.91 | D46: =IFERROR(($A46+$F$6)/(Assumptions!$B$34*12*Assumptions!$C$28),0) -> 16771.291 | E46: =IFERROR(($A46+$F$8)/(Assumptions!$B$35*12*Assumptions!$C$28),0) -> 1956.2357 | F46: =IFERROR(($A46+$F$10)/(Assumptions!$B$36*12*Assumptions!$C$28),0) -> 250.55691
...

Sheet 10K Scenario
A1: The 10,000-Seller Scenario — critical mass
A2: Your thesis: 10,000 sellers is the threshold for attracting buyers. The model supports it financially. At 10,000 sellers the platform carries its full cost load: 3 support staff plus $11,671 of software.
A4: 1. PROFIT AT 10,000 SELLERS, by fee and GMV band (base loss rate)
A5: GMV/seller/mo | B5: Fee | C5: Annual GMV | D5: Gross fee rev | E5: Processing | F5: Loss | G5: Net revenue | H5: Operating cost | I5: Profit | J5: Retained | K5: Distributed | L5: Sellers fundable at CAC
